Workbook

Sheet Colaboradores
A1: ID | B1: Idade | C1: Genero | D1: Area | E1: Cargo | F1: Turno | G1: TempoEmpresaMeses | H1: Salario | I1: Gestor | J1: Admissão | K1: DistanciaKm | L1: Onboarding | M1: HorasExtrasMes | N1: FaltasAno | O1: AvaliacaoDesempenho | P1: Desligado | Q1: Planta | R1: Data Ref | S1: Desligamento | T1: Semana | U1: Mês | V1: Ano
A2: 1780 | B2: 18 | C2: Feminino | D2: Soldagem | E2: Operador | F2: 1º Turno | G2: 55 | H2: 5622 | I2: Carlos | J2: 44084 | K2: 35 | L2: Não | M2: 4 | N2: 7 | O2: 2 | P2: Sim | Q2: 3 | R2: 46174 | S2: 45757 | T2: =TEXT($J2,"ddd") -> qui | U2: =TEXT($J2,"mmm") -> set | V2: =YEAR(J2) -> 2020 | W2: =_xlfn.XLOOKUP(A2,Absenteismo!A:A,Absenteismo!A:A,0) -> 1780
A3: 1361 | B3: 18 | C3: Masculino | D3: Soldagem | E3: Operador | F3: 2º Turno | G3: 44 | H3: 4310 | I3: Carlos | J3: 44476 | K3: 17 | L3: Não | M3: 30 | N3: 1 | O3: 2 | P3: Sim | Q3: 1 | R3: 46174 | S3: 45815 | T3: =TEXT($J3,"ddd") -> qui | U3: =TEXT($J3,"mmm") -> out | V3: =YEAR(J3) -> 2021 | W3: =_xlfn.XLOOKUP(A3,Absenteismo!A:A,Absenteismo!A:A,0) -> 1361
A4: 1180 | B4: 18 | C4: Feminino | D4: Soldagem | E4: Operador | F4: 1º Turno | G4: 55 | H4: 5622 | I4: Carlos | J4: 44342 | K4: 35 | L4: Não | M4: 4 | N4: 7 | O4: 2 | P4: Sim | Q4: 1 | R4: 46174 | S4: 46017 | T4: =TEXT($J4,"ddd") -> qua | U4: =TEXT($J4,"mmm") -> mai | V4: =YEAR(J4) -> 2021 | W4: =_xlfn.XLOOKUP(A4,Absenteismo!A:A,Absenteismo!A:A,0) -> 1180
A5: 1661 | B5: 18 | C5: Masculino | D5: Soldagem | E5: Operador | F5: 2º Turno | G5: 44 | H5: 4310 | I5: Carlos | J5: 44734 | K5: 17 | L5: Não | M5: 30 | N5: 1 | O5: 2 | P5: Sim | Q5: 1 | R5: 46174 | S5: 46075 | T5: =TEXT($J5,"ddd") -> qua | U5: =TEXT($J5,"mmm") -> jun | V5: =YEAR(J5) -> 2022 | W5: =_xlfn.XLOOKUP(A5,Absenteismo!A:A,Absenteismo!A:A,0) -> 1661
A6: 1061 | B6: 18 | C6: Masculino | D6: Soldagem | E6: Operador | F6: 2º Turno | G6: 44 | H6: 4310 | I6: Carlos | J6: 44762 | K6: 17 | L6: Não | M6: 30 | N6: 1 | O6: 2 | P6: Sim | Q6: 1 | R6: 46174 | S6: 46101 | T6: =TEXT($J6,"ddd") -> qua | U6: =TEXT($J6,"mmm") -> jul | V6: =YEAR(J6) -> 2022 | W6: =_xlfn.XLOOKUP(A6,Absenteismo!A:A,Absenteismo!A:A,0) -> 0
A7: 1480 | B7: 18 | C7: Feminino | D7: Soldagem | E7: Operador | F7: 1º Turno | G7: 55 | H7: 5622 | I7: Carlos | J7: 44522 | K7: 35 | L7: Não | M7: 4 | N7: 7 | O7: 2 | P7: Sim | Q7: 3 | R7: 46174 | S7: 46195 | T7: =TEXT($J7,"ddd") -> seg | U7: =TEXT($J7,"mmm") -> nov | V7: =YEAR(J7) -> 2021 | W7: =_xlfn.XLOOKUP(A7,Absenteismo!A:A,Absenteismo!A:A,0) -> 1480
A8: 1016 | B8: 18 | C8: Feminino | D8: Pintura | E8: Operador | F8: 1º Turno | G8: 30 | H8: 3352 | I8: Carlos | J8: 45220 | K8: 40 | L8: Sim | M8: 32 | N8: 3 | O8: 4 | P8: Não | Q8: 2 | R8: 46174 | T8: =TEXT($J8,"ddd") -> sáb | U8: =TEXT($J8,"mmm") -> out | V8: =YEAR(J8) -> 2023 | W8: =_xlfn.XLOOKUP(A8,Absenteismo!A:A,Absenteismo!A:A,0) -> 0
A9: 1316 | B9: 18 | C9: Feminino | D9: Pintura | E9: Operador | F9: 1º Turno | G9: 30 | H9: 3352 | I9: Carlos | J9: 45261 | K9: 56 | L9: Sim | M9: 32 | N9: 3 | O9: 4 | P9: Não | Q9: 2 | R9: 46174 | T9: =TEXT($J9,"ddd") -> sex | U9: =TEXT($J9,"mmm") -> dez | V9: =YEAR(J9) -> 2023 | W9: =_xlfn.XLOOKUP(A9,Absenteismo!A:A,Absenteismo!A:A,0) -> 1316
A10: 1616 | B10: 18 | C10: Feminino | D10: Pintura | E10: Operador | F10: 1º Turno | G10: 30 | H10: 3352 | I10: Carlos | J10: 44925 | K10: 56 | L10: Sim | M10: 32 | N10: 3 | O10: 4 | P10: Não | Q10: 3 | R10: 46174 | T10: =TEXT($J10,"ddd") -> sex | U10: =TEXT($J10,"mmm") -> dez | V10: =YEAR(J10) -> 2022 | W10: =_xlfn.XLOOKUP(A10,Absenteismo!A:A,Absenteismo!A:A,0) -> 1616
A11: 1916 | B11: 18 | C11: Feminino | D11: Pintura | E11: Operador | F11: 1º Turno | G11: 30 | H11: 3352 | I11: Carlos | J11: 45226 | K11: 56 | L11: Sim | M11: 32 | N11: 3 | O11: 4 | P11: Não | Q11: 1 | R11: 46174 | T11: =TEXT($J11,"ddd") -> sex | U11: =TEXT($J11,"mmm") -> out | V11: =YEAR(J11) -> 2023 | W11: =_xlfn.XLOOKUP(A11,Absenteismo!A:A,Absenteismo!A:A,0) -> 1916
A12: 1961 | B12: 18 | C12: Masculino | D12: Soldagem | E12: Operador | F12: 2º Turno | G12: 44 | H12: 4310 | I12: Carlos | J12: 44486 | K12: 17 | L12: Não | M12: 30 | N12: 1 | O12: 2 | P12: Não | Q12: 1 | R12: 46174 | T12: =TEXT($J12,"ddd") -> dom | U12: =TEXT($J12,"mmm") -> out | V12: =YEAR(J12) -> 2021 | W12: =_xlfn.XLOOKUP(A12,Absenteismo!A:A,Absenteismo!A:A,0) -> 1961
A13: 2080 | B13: 18 | C13: Feminino | D13: Soldagem | E13: Operador | F13: 1º Turno | G13: 55 | H13: 5622 | I13: Carlos | J13: 44319 | K13: 35 | L13: Não | M13: 4 | N13: 7 | O13: 2 | P13: Não | Q13: 3 | R13: 46174 | T13: =TEXT($J13,"ddd") -> seg | U13: =TEXT($J13,"mmm") -> mai | V13: =YEAR(J13) -> 2021 | W13: =_xlfn.XLOOKUP(A13,Absenteismo!A:A,Absenteismo!A:A,0) -> 2080
A14: 1269 | B14: 19 | C14: Masculino | D14: Montagem | E14: Operador | F14: 2º Turno | G14: 68 | H14: 5728 | I14: Marcos | J14: 43817 | K14: 15 | L14: Não | M14: 6 | N14: 3 | O14: 3 | P14: Sim | Q14: 1 | R14: 46174 | S14: 45887 | T14: =TEXT($J14,"ddd") -> qua | U14: =TEXT($J14,"mmm") -> dez | V14: =YEAR(J14) -> 2019 | W14: =_xlfn.XLOOKUP(A14,Absenteismo!A:A,Absenteismo!A:A,0) -> 1269
A15: 1569 | B15: 19 | C15: Masculino | D15: Montagem | E15: Operador | F15: 2º Turno | G15: 68 | H15: 5728 | I15: Marcos | J15: 43972 | K15: 15 | L15: Não | M15: 6 | N15: 3 | O15: 3 | P15: Sim | Q15: 2 | R15: 46174 | S15: 46043 | T15: =TEXT($J15,"ddd") -> qui | U15: =TEXT($J15,"mmm") -> mai | V15: =YEAR(J15) -> 2020 | W15: =_xlfn.XLOOKUP(A15,Absenteismo!A:A,Absenteismo!A:A,0) -> 1569
A16: 1869 | B16: 19 | C16: Masculino | D16: Montagem | E16: Operador | F16: 2º Turno | G16: 68 | H16: 5728 | I16: Marcos | J16: 44097 | K16: 15 | L16: Não | M16: 6 | N16: 3 | O16: 3 | P16: Sim | Q16: 3 | R16: 46174 | S16: 46165 | T16: =TEXT($J16,"ddd") -> qua | U16: =TEXT($J16,"mmm") -> set | V16: =YEAR(J16) -> 2020 | W16: =_xlfn.XLOOKUP(A16,Absenteismo!A:A,Absenteismo!A:A,0) -> 1869
A17: 1184 | B17: 19 | C17: Feminino | D17: Montagem | E17: Operador | F17: 1º Turno | G17: 77 | H17: 3075 | I17: Juliana | J17: 43427 | K17: 39 | L17: Sim | M17: 3 | N17: 3 | O17: 2 | P17: Não | Q17: 3 | R17: 46174 | T17: =TEXT($J17,"ddd") -> sex | U17: =TEXT($J17,"mmm") -> nov | V17: =YEAR(J17) -> 2018 | W17: =_xlfn.XLOOKUP(A17,Absenteismo!A:A,Absenteismo!A:A,0) -> 0
A18: 1484 | B18: 19 | C18: Feminino | D18: Montagem | E18: Operador | F18: 1º Turno | G18: 77 | H18: 3075 | I18: Juliana | J18: 43605 | K18: 39 | L18: Sim | M18: 3 | N18: 3 | O18: 2 | P18: Não | Q18: 3 | R18: 46174 | T18: =TEXT($J18,"ddd") -> seg | U18: =TEXT($J18,"mmm") -> mai | V18: =YEAR(J18) -> 2019 | W18: =_xlfn.XLOOKUP(A18,Absenteismo!A:A,Absenteismo!A:A,0) -> 1484
A19: 1784 | B19: 19 | C19: Feminino | D19: Montagem | E19: Operador | F19: 1º Turno | G19: 77 | H19: 3075 | I19: Juliana | J19: 43809 | K19: 39 | L19: Sim | M19: 3 | N19: 3 | O19: 2 | P19: Não | Q19: 3 | R19: 46174 | T19: =TEXT($J19,"ddd") -> ter | U19: =TEXT($J19,"mmm") -> dez | V19: =YEAR(J19) -> 2019 | W19: =_xlfn.XLOOKUP(A19,Absenteismo!A:A,Absenteismo!A:A,0) -> 1784
A20: 2084 | B20: 19 | C20: Feminino | D20: Montagem | E20: Operador | F20: 1º Turno | G20: 77 | H20: 3075 | I20: Juliana | J20: 43781 | K20: 39 | L20: Sim | M20: 3 | N20: 3 | O20: 2 | P20: Não | Q20: 2 | R20: 46174 | T20: =TEXT($J20,"ddd") -> ter | U20: =TEXT($J20,"mmm") -> nov | V20: =YEAR(J20) -> 2019 | W20: =_xlfn.XLOOKUP(A20,Absenteismo!A:A,Absenteismo!A:A,0) -> 2084
A21: 2169 | B21: 19 | C21: Masculino | D21: Montagem | E21: Operador | F21: 2º Turno | G21: 68 | H21: 5728 | I21: Marcos | J21: 43789 | K21: 15 | L21: Não | M21: 6 | N21: 3 | O21: 3 | P21: Não | Q21: 1 | R21: 46174 | T21: =TEXT($J21,"ddd") -> qua | U21: =TEXT($J21,"mmm") -> nov | V21: =YEAR(J21) -> 2019 | W21: =_xlfn.XLOOKUP(A21,Absenteismo!A:A,Absenteismo!A:A,0) -> 2169
A22: 1686 | B22: 20 | C22: Masculino | D22: Logistica | E22: Operador | F22: 1º Turno | G22: 75 | H22: 5788 | I22: Fernanda | J22: 43739 | K22: 6 | L22: Não | M22: 20 | N22: 11 | O22: 5 | P22: Sim | Q22: 2 | R22: 46174 | S22: 46023 | T22: =TEXT($J22,"ddd") -> ter | U22: =TEXT($J22,"mmm") -> out | V22: =YEAR(J22) -> 2019 | W22: =_xlfn.XLOOKUP(A22,Absenteismo!A:A,Absenteismo!A:A,0) -> 0
A23: 1386 | B23: 20 | C23: Masculino | D23: Logistica | E23: Operador | F23: 1º Turno | G23: 75 | H23: 5788 | I23: Fernanda | J23: 43848 | K23: 6 | L23: Não | M23: 20 | N23: 11 | O23: 5 | P23: Sim | Q23: 1 | R23: 46174 | S23: 46130 | T23: =TEXT($J23,"ddd") -> sáb | U23: =TEXT($J23,"mmm") -> jan | V23: =YEAR(J23) -> 2020 | W23: =_xlfn.XLOOKUP(A23,Absenteismo!A:A,Absenteismo!A:A,0) -> 1386
A24: 1086 | B24: 20 | C24: Masculino | D24: Logistica | E24: Operador | F24: 1º Turno | G24: 75 | H24: 5788 | I24: Fernanda | J24: 43853 | K24: 6 | L24: Não | M24: 20 | N24: 11 | O24: 5 | P24: Não | Q24: 3 | R24: 46174 | T24: =TEXT($J24,"ddd") -> qui | U24: =TEXT($J24,"mmm") -> jan | V24: =YEAR(J24) -> 2020 | W24: =_xlfn.XLOOKUP(A24,Absenteismo!A:A,Absenteismo!A:A,0) -> 1086
A25: 1110 | B25: 20 | C25: Masculino | D25: Montagem | E25: Operador | F25: 1º Turno | G25: 111 | H25: 5364 | I25: Marcos | J25: 42394 | K25: 28 | L25: Sim | M25: 26 | N25: 4 | O25: 2 | P25: Não | Q25: 2 | R25: 46174 | T25: =TEXT($J25,"ddd") -> seg | U25: =TEXT($J25,"mmm") -> jan | V25: =YEAR(J25) -> 2016 | W25: =_xlfn.XLOOKUP(A25,Absenteismo!A:A,Absenteismo!A:A,0) -> 0
A26: 1230 | B26: 20 | C26: Masculino | D26: Soldagem | E26: Operador | F26: 2º Turno | G26: 14 | H26: 4827 | I26: Ricardo | J26: 45558 | K26: 56 | L26: Não | M26: 28 | N26: 4 | O26: 4 | P26: Não | Q26: 3 | R26: 46174 | T26: =TEXT($J26,"ddd") -> seg | U26: =TEXT($J26,"mmm") -> set | V26: =YEAR(J26) -> 2024 | W26: =_xlfn.XLOOKUP(A26,Absenteismo!A:A,Absenteismo!A:A,0) -> 0
A27: 1410 | B27: 20 | C27: Masculino | D27: Montagem | E27: Operador | F27: 1º Turno | G27: 111 | H27: 5364 | I27: Marcos | J27: 42490 | K27: 28 | L27: Sim | M27: 26 | N27: 4 | O27: 2 | P27: Não | Q27: 1 | R27: 46174 | T27: =TEXT($J27,"ddd") -> sáb | U27: =TEXT($J27,"mmm") -> abr | V27: =YEAR(J27) -> 2016 | W27: =_xlfn.XLOOKUP(A27,Absenteismo!A:A,Absenteismo!A:A,0) -> 1410
A28: 1530 | B28: 20 | C28: Masculino | D28: Soldagem | E28: Operador | F28: 2º Turno | G28: 14 | H28: 4827 | I28: Ricardo | J28: 45344 | K28: 56 | L28: Não | M28: 28 | N28: 4 | O28: 4 | P28: Não | Q28: 1 | R28: 46174 | T28: =TEXT($J28,"ddd") -> qui | U28: =TEXT($J28,"mmm") -> fev | V28: =YEAR(J28) -> 2024 | W28: =_xlfn.XLOOKUP(A28,Absenteismo!A:A,Absenteismo!A:A,0) -> 0
A29: 1710 | B29: 20 | C29: Masculino | D29: Montagem | E29: Operador | F29: 1º Turno | G29: 111 | H29: 5364 | I29: Marcos | J29: 42529 | K29: 28 | L29: Sim | M29: 26 | N29: 4 | O29: 2 | P29: Não | Q29: 3 | R29: 46174 | T29: =TEXT($J29,"ddd") -> qua | U29: =TEXT($J29,"mmm") -> jun | V29: =YEAR(J29) -> 2016 | W29: =_xlfn.XLOOKUP(A29,Absenteismo!A:A,Absenteismo!A:A,0) -> 1710
A30: 1830 | B30: 20 | C30: Masculino | D30: Soldagem | E30: Operador | F30: 2º Turno | G30: 14 | H30: 4827 | I30: Ricardo | J30: 45703 | K30: 41 | L30: Não | M30: 28 | N30: 4 | O30: 4 | P30: Não | Q30: 3 | R30: 46174 | T30: =TEXT($J30,"ddd") -> sáb | U30: =TEXT($J30,"mmm") -> fev | V30: =YEAR(J30) -> 2025 | W30: =_xlfn.XLOOKUP(A30,Absenteismo!A:A,Absenteismo!A:A,0) -> 0
A31: 2010 | B31: 20 | C31: Masculino | D31: Montagem | E31: Operador | F31: 1º Turno | G31: 111 | H31: 5364 | I31: Marcos | J31: 42616 | K31: 28 | L31: Sim | M31: 26 | N31: 4 | O31: 2 | P31: Não | Q31: 3 | R31: 46174 | T31: =TEXT($J31,"ddd") -> sáb | U31: =TEXT($J31,"mmm") -> set | V31: =YEAR(J31) -> 2016 | W31: =_xlfn.XLOOKUP(A31,Absenteismo!A:A,Absenteismo!A:A,0) -> 2010
A32: 2130 | B32: 20 | C32: Masculino | D32: Soldagem | E32: Operador | F32: 2º Turno | G32: 14 | H32: 4827 | I32: Ricardo | J32: 45590 | K32: 56 | L32: Não | M32: 28 | N32: 4 | O32: 4 | P32: Não | Q32: 2 | R32: 46174 | T32: =TEXT($J32,"ddd") -> sex | U32: =TEXT($J32,"mmm") -> out | V32: =YEAR(J32) -> 2024 | W32: =_xlfn.XLOOKUP(A32,Absenteismo!A:A,Absenteismo!A:A,0) -> 0
A33: 1986 | B33: 20 | C33: Masculino | D33: Logistica | E33: Operador | F33: 1º Turno | G33: 75 | H33: 5788 | I33: Fernanda | J33: 43562 | K33: 6 | L33: Não | M33: 20 | N33: 11 | O33: 5 | P33: Não | Q33: 1 | R33: 46174 | T33: =TEXT($J33,"ddd") -> dom | U33: =TEXT($J33,"mmm") -> abr | V33: =YEAR(J33) -> 2019 | W33: =_xlfn.XLOOKUP(A33,Absenteismo!A:A,Absenteismo!A:A,0) -> 1986
A34: 1022 | B34: 21 | C34: Feminino | D34: Soldagem | E34: Operador | F34: 3º Turno | G34: 118 | H34: 7150 | I34: Fernanda | J34: 42452 | K34: 4 | L34: Não | M34: 5 | N34: 2 | O34: 2 | P34: Não | Q34: 2 | R34: 46174 | T34: =TEXT($J34,"ddd") -> qua | U34: =TEXT($J34,"mmm") -> mar | V34: =YEAR(J34) -> 2016 | W34: =_xlfn.XLOOKUP(A34,Absenteismo!A:A,Absenteismo!A:A,0) -> 0
A35: 1028 | B35: 21 | C35: Feminino | D35: Pintura | E35: Operador | F35: 2º Turno | G35: 6 | H35: 2829 | I35: Ricardo | J35: 45985 | K35: 41 | L35: Sim | M35: 16 | N35: 2 | O35: 5 | P35: Não | Q35: 1 | R35: 46174 | T35: =TEXT($J35,"ddd") -> seg | U35: =TEXT($J35,"mmm") -> nov | V35: =YEAR(J35) -> 2025 | W35: =_xlfn.XLOOKUP(A35,Absenteismo!A:A,Absenteismo!A:A,0) -> 0
... A73: 2170 | B73: 21 | C73: Feminino | D73: Soldagem | E73: Operador | F73: 2º Turno | G73: 46 | H73: 4223 | I73: Fernanda | J73: 44583 | K73: 16 | L73: Sim | M73: 22 | N73: 9 | O73: 2 | P73: Não | Q73: 2 | R73: 46174 | T73: =TEXT($J73,"ddd") -> sáb | U73: =TEXT($J73,"mmm") -> jan | V73: =YEAR(J73) -> 2022 | W73: =_xlfn.XLOOKUP(A73,Absenteismo!A:A,Absenteismo!A:A,0) -> 0
A74: 1114 | B74: 22 | C74: Feminino | D74: Qualidade | E74: Inspetor | F74: 2º Turno | G74: 97 | H74: 7418 | I74: Marcos | J74: 42823 | K74: 29 | L74: Sim | M74: 20 | N74: 10 | O74: 4 | P74: Sim | Q74: 2 | R74: 46174 | S74: 45776 | T74: =TEXT($J74,"ddd") -> qua | U74: =TEXT($J74,"mmm") -> mar | V74: =YEAR(J74) -> 2017 | W74: =_xlfn.XLOOKUP(A74,Absenteismo!A:A,Absenteismo!A:A,0) -> 1114
A75: 1288 | B75: 22 | C75: Feminino | D75: Soldagem | E75: Operador | F75: 2º Turno | G75: 71 | H75: 5471 | I75: Ricardo | J75: 43638 | K75: 34 | L75: Sim | M75: 0 | N75: 12 | O75: 5 | P75: Sim | Q75: 2 | R75: 46174 | S75: 45799 | T75: =TEXT($J75,"ddd") -> sáb | U75: =TEXT($J75,"mmm") -> jun | V75: =YEAR(J75) -> 2019 | W75: =_xlfn.XLOOKUP(A75,Absenteismo!A:A,Absenteismo!A:A,0) -> 0
A76: 1215 | B76: 22 | C76: Masculino | D76: Pintura | E76: Operador | F76: 1º Turno | G76: 82 | H76: 5280 | I76: Fernanda | J76: 43318 | K76: 17 | L76: Sim | M76: 27 | N76: 12 | O76: 5 | P76: Sim | Q76: 2 | R76: 46174 | S76: 45814 | T76: =TEXT($J76,"ddd") -> seg | U76: =TEXT($J76,"mmm") -> ago | V76: =YEAR(J76) -> 2018 | W76: =_xlfn.XLOOKUP(A76,Absenteismo!A:A,Absenteismo!A:A,0) -> 1215
A77: 1515 | B77: 22 | C77: Masculino | D77: Pintura | E77: Operador | F77: 1º Turno | G77: 82 | H77: 5280 | I77: Fernanda | J77: 43395 | K77: 17 | L77: Sim | M77: 27 | N77: 12 | O77: 5 | P77: Sim | Q77: 1 | R77: 46174 | S77: 45891 | T77: =TEXT($J77,"ddd") -> seg | U77: =TEXT($J77,"mmm") -> out | V77: =YEAR(J77) -> 2018 | W77: =_xlfn.XLOOKUP(A77,Absenteismo!A:A,Absenteismo!A:A,0) -> 1515
...

Sheet Absenteismo
A1: ID | B1: Idade | C1: Genero | D1: Area | E1: Cargo | F1: Turno | G1: FaltasAno | H1: Desligado | I1: Planta | J1: Data | K1: Data Ref | L1: Semana | M1: Mês | N1: Ano | O1: Desligamento | P1: Check
A2: 1968 | B2: 54 | C2: Feminino | D2: Qualidade | E2: Inspetor | F2: 3º Turno | G2: Medico | H2: Não | I2: 3 | J2: 46153 | K2: =DATE(YEAR(J2),MONTH(J2),1) -> 46143 | L2: =TEXT(J2,"ddd") -> seg | M2: =TEXT($J2,"mmm") -> mai | N2: =YEAR(J2) -> 2026 | P2: =CONCATENATE(A2,J2) -> 196846153
A3: 1968 | B3: 54 | C3: Feminino | D3: Qualidade | E3: Inspetor | F3: 3º Turno | G3: Medico | H3: Não | I3: 3 | J3: 46173 | K3: =DATE(YEAR(J3),MONTH(J3),1) -> 46143 | L3: dom | M3: mai | N3: 2025 | P3: =CONCATENATE(A3,J3) -> 196846173
A4: 1972 | B4: 49 | C4: Feminino | D4: Montagem | E4: Operador | F4: 3º Turno | G4: Medico | H4: Não | I4: 3 | J4: 46157 | K4: =DATE(YEAR(J4),MONTH(J4),1) -> 46143 | L4: =TEXT(J4,"ddd") -> sex | M4: =TEXT($J4,"mmm") -> mai | N4: =YEAR(J4) -> 2026 | P4: =CONCATENATE(A4,J4) -> 197246157
A5: 1972 | B5: 49 | C5: Feminino | D5: Montagem | E5: Operador | F5: 3º Turno | G5: Medico | H5: Não | I5: 3 | J5: 46138 | K5: =DATE(YEAR(J5),MONTH(J5),1) -> 46113 | L5: qui | M5: mai | N5: 2025 | P5: =CONCATENATE(A5,J5) -> 197246138
A6: 1976 | B6: 38 | C6: Feminino | D6: Qualidade | E6: Analista | F6: 3º Turno | G6: Medico | H6: Não | I6: 2 | J6: 46181 | K6: =DATE(YEAR(J6),MONTH(J6),1) -> 46174 | L6: =TEXT(J6,"ddd") -> seg | M6: =TEXT($J6,"mmm") -> jun | N6: =YEAR(J6) -> 2026 | P6: =CONCATENATE(A6,J6) -> 197646181
A7: 1976 | B7: 38 | C7: Feminino | D7: Qualidade | E7: Analista | F7: 3º Turno | G7: Medico | H7: Não | I7: 2 | J7: 46173 | K7: =DATE(YEAR(J7),MONTH(J7),1) -> 46143 | L7: =TEXT(J7,"ddd") -> dom | M7: =TEXT($J7,"mmm") -> mai | N7: =YEAR(J7) -> 2026 | P7: =CONCATENATE(A7,J7) -> 197646173
A8: 1976 | B8: 38 | C8: Feminino | D8: Qualidade | E8: Analista | F8: 3º Turno | G8: Medico | H8: Não | I8: 2 | J8: 46130 | K8: =DATE(YEAR(J8),MONTH(J8),1) -> 46113 | L8: sex | M8: abr | N8: 2025 | P8: =CONCATENATE(A8,J8) -> 197646130
A9: 1976 | B9: 38 | C9: Feminino | D9: Qualidade | E9: Analista | F9: 3º Turno | G9: Medico | H9: Não | I9: 2 | J9: 46150 | K9: =DATE(YEAR(J9),MONTH(J9),1) -> 46143 | L9: qui | M9: mai | N9: 2025 | P9: =CONCATENATE(A9,J9) -> 197646150
A10: 1977 | B10: 27 | C10: Masculino | D10: Qualidade | E10: Analista | F10: 3º Turno | G10: Medico | H10: Não | I10: 3 | J10: 46138 | K10: =DATE(YEAR(J10),MONTH(J10),1) -> 46113 | L10: =TEXT(J10,"ddd") -> dom | M10: =TEXT($J10,"mmm") -> abr | N10: =YEAR(J10) -> 2026 | P10: =CONCATENATE(A10,J10) -> 197746138
A11: 1977 | B11: 27 | C11: Masculino | D11: Qualidade | E11: Analista | F11: 3º Turno | G11: Medico | H11: Não | I11: 3 | J11: 46170 | K11: =DATE(YEAR(J11),MONTH(J11),1) -> 46143 | L11: =TEXT(J11,"ddd") -> qui | M11: =TEXT($J11,"mmm") -> mai | N11: =YEAR(J11) -> 2026 | P11: =CONCATENATE(A11,J11) -> 197746170
A12: 1977 | B12: 27 | C12: Masculino | D12: Qualidade | E12: Analista | F12: 3º Turno | G12: Medico | H12: Não | I12: 3 | J12: 46164 | K12: =DATE(YEAR(J12),MONTH(J12),1) -> 46143 | L12: qui | M12: mai | N12: 2025 | P12: =CONCATENATE(A12,J12) -> 197746164
A13: 1977 | B13: 27 | C13: Masculino | D13: Qualidade | E13: Analista | F13: 3º Turno | G13: Medico | H13: Não | I13: 3 | J13: 46168 | K13: =DATE(YEAR(J13),MONTH(J13),1) -> 46143 | L13: seg | M13: mai | N13: 2025 | P13: =CONCATENATE(A13,J13) -> 197746168
A14: 1980 | B14: 24 | C14: Feminino | D14: Soldagem | E14: Operador | F14: 3º Turno | G14: Medico | H14: Não | I14: 2 | J14: 46134 | K14: =DATE(YEAR(J14),MONTH(J14),1) -> 46113 | L14: =TEXT(J14,"ddd") -> qua | M14: =TEXT($J14,"mmm") -> abr | N14: =YEAR(J14) -> 2026 | P14: =CONCATENATE(A14,J14) -> 198046134
A15: 1980 | B15: 24 | C15: Feminino | D15: Soldagem | E15: Operador | F15: 3º Turno | G15: Medico | H15: Não | I15: 2 | J15: 46173 | K15: =DATE(YEAR(J15),MONTH(J15),1) -> 46143 | L15: ter | M15: abr | N15: 2025 | P15: =CONCATENATE(A15,J15) -> 198046173
A16: 1983 | B16: 37 | C16: Masculino | D16: Pintura | E16: Operador | F16: 2º Turno | G16: Medico | H16: Não | I16: 3 | J16: 46170 | K16: =DATE(YEAR(J16),MONTH(J16),1) -> 46143 | L16: =TEXT(J16,"ddd") -> qui | M16: =TEXT($J16,"mmm") -> mai | N16: =YEAR(J16) -> 2026 | P16: =CONCATENATE(A16,J16) -> 198346170
A17: 1983 | B17: 37 | C17: Masculino | D17: Pintura | E17: Operador | F17: 2º Turno | G17: Medico | H17: Não | I17: 3 | J17: 46138 | K17: =DATE(YEAR(J17),MONTH(J17),1) -> 46113 | L17: =TEXT(J17,"ddd") -> dom | M17: =TEXT($J17,"mmm") -> abr | N17: =YEAR(J17) -> 2026 | P17: =CONCATENATE(A17,J17) -> 198346138
A18: 1983 | B18: 37 | C18: Masculino | D18: Pintura | E18: Operador | F18: 2º Turno | G18: Medico | H18: Não | I18: 3 | J18: 46156 | K18: =DATE(YEAR(J18),MONTH(J18),1) -> 46143 | L18: qua | M18: mai | N18: 2025 | P18: =CONCATENATE(A18,J18) -> 198346156
A19: 1983 | B19: 37 | C19: Masculino | D19: Pintura | E19: Operador | F19: 2º Turno | G19: Medico | H19: Não | I19: 3 | J19: 46173 | K19: =DATE(YEAR(J19),MONTH(J19),1) -> 46143 | L19: sáb | M19: mai | N19: 2025 | P19: =CONCATENATE(A19,J19) -> 198346173
A20: 1986 | B20: 20 | C20: Masculino | D20: Logistica | E20: Operador | F20: 1º Turno | G20: Medico | H20: Não | I20: 1 | J20: 46170 | K20: =DATE(YEAR(J20),MONTH(J20),1) -> 46143 | L20: =TEXT(J20,"ddd") -> qui | M20: =TEXT($J20,"mmm") -> mai | N20: =YEAR(J20) -> 2026 | P20: =CONCATENATE(A20,J20) -> 198646170
A21: 1986 | B21: 20 | C21: Masculino | D21: Logistica | E21: Operador | F21: 1º Turno | G21: Medico | H21: Não | I21: 1 | J21: 46123 | K21: =DATE(YEAR(J21),MONTH(J21),1) -> 46113 | L21: sex | M21: abr | N21: 2025 | P21: =CONCATENATE(A21,J21) -> 198646123
A22: 1988 | B22: 39 | C22: Feminino | D22: Soldagem | E22: Operador | F22: 1º Turno | G22: Medico | H22: Não | I22: 1 | J22: 46173 | K22: =DATE(YEAR(J22),MONTH(J22),1) -> 46143 | L22: =TEXT(J22,"ddd") -> dom | M22: =TEXT($J22,"mmm") -> mai | N22: =YEAR(J22) -> 2026 | P22: =CONCATENATE(A22,J22) -> 198846173
A23: 1988 | B23: 39 | C23: Feminino | D23: Soldagem | E23: Operador | F23: 1º Turno | G23: Medico | H23: Não | I23: 1 | J23: 46170 | K23: =DATE(YEAR(J23),MONTH(J23),1) -> 46143 | L23: =TEXT(J23,"ddd") -> qui | M23: =TEXT($J23,"mmm") -> mai | N23: =YEAR(J23) -> 2026 | P23: =CONCATENATE(A23,J23) -> 198846170
A24: 1988 | B24: 39 | C24: Feminino | D24: Soldagem | E24: Operador | F24: 1º Turno | G24: Medico | H24: Não | I24: 1 | J24: 46138 | K24: =DATE(YEAR(J24),MONTH(J24),1) -> 46113 | L24: =TEXT(J24,"ddd") -> dom | M24: =TEXT($J24,"mmm") -> abr | N24: =YEAR(J24) -> 2026 | P24: =CONCATENATE(A24,J24) -> 198846138
A25: 1988 | B25: 39 | C25: Feminino | D25: Soldagem | E25: Operador | F25: 1º Turno | G25: Medico | H25: Não | I25: 1 | J25: 46131 | K25: =DATE(YEAR(J25),MONTH(J25),1) -> 46113 | L25: sáb | M25: abr | N25: 2025 | P25: =CONCATENATE(A25,J25) -> 198846131
A26: 1988 | B26: 39 | C26: Feminino | D26: Soldagem | E26: Operador | F26: 1º Turno | G26: Medico | H26: Não | I26: 1 | J26: 46135 | K26: =DATE(YEAR(J26),MONTH(J26),1) -> 46113 | L26: qua | M26: abr | N26: 2025 | P26: =CONCATENATE(A26,J26) -> 198846135
A27: 1988 | B27: 39 | C27: Feminino | D27: Soldagem | E27: Operador | F27: 1º Turno | G27: Medico | H27: Não | I27: 1 | J27: 46162 | K27: =DATE(YEAR(J27),MONTH(J27),1) -> 46143 | L27: ter | M27: mai | N27: 2025 | P27: =CONCATENATE(A27,J27) -> 198846162
A28: 1991 | B28: 49 | C28: Feminino | D28: Montagem | E28: Operador | F28: 3º Turno | G28: Medico | H28: Não | I28: 1 | J28: 46055 | K28: =DATE(YEAR(J28),MONTH(J28),1) -> 46054 | L28: =TEXT(J28,"ddd") -> seg | M28: =TEXT($J28,"mmm") -> fev | N28: =YEAR(J28) -> 2026 | P28: =CONCATENATE(A28,J28) -> 199146055
A29: 1991 | B29: 49 | C29: Feminino | D29: Montagem | E29: Operador | F29: 3º Turno | G29: Medico | H29: Não | I29: 1 | J29: 46165 | K29: =DATE(YEAR(J29),MONTH(J29),1) -> 46143 | L29: sex | M29: mai | N29: 2025 | P29: =CONCATENATE(A29,J29) -> 199146165
A30: 1994 | B30: 26 | C30: Feminino | D30: Montagem | E30: Operador | F30: 3º Turno | G30: Medico | H30: Não | I30: 3 | J30: 46124 | K30: =DATE(YEAR(J30),MONTH(J30),1) -> 46113 | L30: =TEXT(J30,"ddd") -> dom | M30: =TEXT($J30,"mmm") -> abr | N30: =YEAR(J30) -> 2026 | P30: =CONCATENATE(A30,J30) -> 199446124
A31: 1994 | B31: 26 | C31: Feminino | D31: Montagem | E31: Operador | F31: 3º Turno | G31: Medico | H31: Não | I31: 3 | J31: 46165 | K31: =DATE(YEAR(J31),MONTH(J31),1) -> 46143 | L31: =TEXT(J31,"ddd") -> sáb | M31: =TEXT($J31,"mmm") -> mai | N31: =YEAR(J31) -> 2026 | P31: =CONCATENATE(A31,J31) -> 199446165
A32: 1994 | B32: 26 | C32: Feminino | D32: Montagem | E32: Operador | F32: 3º Turno | G32: Medico | H32: Não | I32: 3 | J32: 46173 | K32: =DATE(YEAR(J32),MONTH(J32),1) -> 46143 | L32: sáb | M32: abr | N32: 2025 | P32: =CONCATENATE(A32,J32) -> 199446173
A33: 1994 | B33: 26 | C33: Feminino | D33: Montagem | E33: Operador | F33: 3º Turno | G33: Medico | H33: Não | I33: 3 | J33: 46174 | K33: =DATE(YEAR(J33),MONTH(J33),1) -> 46174 | L33: sex | M33: mai | N33: 2025 | P33: =CONCATENATE(A33,J33) -> 199446174
A34: 1995 | B34: 52 | C34: Masculino | D34: Logistica | E34: Operador | F34: 1º Turno | G34: Medico | H34: Não | I34: 2 | J34: 46201 | K34: =DATE(YEAR(J34),MONTH(J34),1) -> 46174 | L34: =TEXT(J34,"ddd") -> dom | M34: =TEXT($J34,"mmm") -> jun | N34: =YEAR(J34) -> 2026 | P34: =CONCATENATE(A34,J34) -> 199546201
A35: 1995 | B35: 52 | C35: Masculino | D35: Logistica | E35: Operador | F35: 1º Turno | G35: Medico | H35: Não | I35: 2 | J35: 46162 | K35: =DATE(YEAR(J35),MONTH(J35),1) -> 46143 | L35: ter | M35: mai | N35: 2025 | P35: =CONCATENATE(A35,J35) -> 199546162
A36: 1997 | B36: 32 | C36: Feminino | D36: Pintura | E36: Operador | F36: 3º Turno | G36: Medico | H36: Não | I36: 2 | J36: 46129 | K36: =DATE(YEAR(J36),MONTH(J36),1) -> 46113 | L36: =TEXT(J36,"ddd") -> sex | M36: =TEXT($J36,"mmm") -> abr | N36: =YEAR(J36) -> 2026 | P36: =CONCATENATE(A36,J36) -> 199746129
A37: 1997 | B37: 32 | C37: Feminino | D37: Pintura | E37: Operador | F37: 3º Turno | G37: Medico | H37: Não | I37: 2 | J37: 46174 | K37: =DATE(YEAR(J37),MONTH(J37),1) -> 46174 | L37: =TEXT(J37,"ddd") -> seg | M37: =TEXT($J37,"mmm") -> jun | N37: =YEAR(J37) -> 2026 | P37: =CONCATENATE(A37,J37) -> 199746174
A38: 1997 | B38: 32 | C38: Feminino | D38: Pintura | E38: Operador | F38: 3º Turno | G38: Medico | H38: Não | I38: 2 | J38: 46173 | K38: =DATE(YEAR(J38),MONTH(J38),1) -> 46143 | L38: =TEXT(J38,"ddd") -> dom | M38: =TEXT($J38,"mmm") -> mai | N38: =YEAR(J38) -> 2026 | P38: =CONCATENATE(A38,J38) -> 199746173
A39: 1997 | B39: 32 | C39: Feminino | D39: Pintura | E39: Operador | F39: 3º Turno | G39: Medico | H39: Não | I39: 2 | J39: 46201 | K39: =DATE(YEAR(J39),MONTH(J39),1) -> 46174 | L39: qui | M39: abr | N39: 2025 | P39: =CONCATENATE(A39,J39) -> 199746201
A40: 1997 | B40: 32 | C40: Feminino | D40: Pintura | E40: Operador | F40: 3º Turno | G40: Medico | H40: Não | I40: 2 | J40: 46159 | K40: =DATE(YEAR(J40),MONTH(J40),1) -> 46143 | L40: sáb | M40: mai | N40: 2025 | P40: =CONCATENATE(A40,J40) -> 199746159
...

Sheet Planilha1
C3: Planta | D3: (Tudo) | J3: Planta | K3: (Tudo)
C5: Contagem de ID | D5: Rótulos de Coluna | J5: Contagem de FaltasAno | K5: Rótulos de Coluna
C6: Rótulos de Linha | D6: 2025 | E6: 2026 | F6: Total Geral | J6: Rótulos de Linha | K6: 2025 | L6: 2026 | M6: Total Geral
C7: Afastamento | D7: 1429 | E7: 306 | F7: 1735 | J7: jan | K7: 148 | L7: 41 | M7: 189
C8: Ferias | D8: 430 | E8: 130 | F8: 560 | J8: fev | K8: 206 | L8: 333 | M8: 539
C9: Injustificada | D9: 69 | E9: 4 | F9: 73 | J9: mar | K9: 205 | L9: 365 | M9: 570
C10: Legal | D10: 158 | E10: 49 | F10: 207 | J10: abr | K10: 573 | L10: 279 | M10: 852
C11: Medico | D11: 2834 | E11: 1180 | F11: 4014 | J11: mai | K11: 706 | L11: 254 | M11: 960
C12: Outros | D12: 190 | E12: 40 | F12: 230 | J12: jun | K12: 509 | L12: 437 | M12: 946
C13: Total Geral | D13: 5110 | E13: 1709 | F13: 6819 | J13: jul | K13: 560 | M13: 560
J14: ago | K14: 482 | M14: 482
J15: set | K15: 447 | M15: 447
C16: Faltas Total | D16: =D15+D13 -> 5110 | E16: =E15+E13 -> 1709 | F16: =F15+F13 -> 6819 | J16: out | K16: 464 | M16: 464
J17: nov | K17: 439 | M17: 439
D18: 12 meses | E18: 6 meses | F18: 0.1 | J18: dez | K18: 371 | M18: 371
C19: Headcount | D19: 888 | E19: 888 | F19: 888 | J19: Total Geral | K19: 5110 | L19: 1709 | M19: 6819
C20: Dias | D20: 220 | E20: =D20/2 -> 110 | F20: =SUM(D20:E20) -> 330
C21: Available Days | D21: =D19*D20 -> 195360 | E21: =E19*E20 -> 97680 | F21: =F19*F20 -> 293040
C23: % Abs geral | D23: =D16/(D19*D20) -> 0.026156839 | E23: =E16/(E19*E20) -> 0.017495905 | F23: =(F13+F16)/(F19*F20) -> 0.046539722
C24: Abs | D24: =(D16-D8)/(D19*D20) -> 0.023955774 | E24: =(E16-E8)/(E19*E20) -> 0.016165029 | F24: =(F16-F8)/(F19*F20) -> 0.021358859
